<?xml version="1.0" ?>
<!-- =================================================================================== -->
<!-- |    This document was autogenerated by xacro from panda_arm_hand.urdf.xacro      | -->
<!-- |    EDITING THIS FILE BY HAND IS NOT RECOMMENDED                                 | -->
<!-- =================================================================================== -->
<robot name="panda" xmlns:xacro="http://www.ros.org/wiki/xacro">
  <link name="panda_link0">
  	<inertial>
      <origin rpy="0 0 0" xyz="0 0 0.05"/>
       <mass value="2.9"/>
       <inertia ixx="0.1" ixy="0" ixz="0" iyy="0.1" iyz="0" izz="0.1"/>
    </inertial>
    <visual>
      <geometry>
        <mesh filename="package://meshes/collision/link0.obj"/>
      </geometry>
      <material name="panda_white">
    		<color rgba="0.9 0.9 0.9 1."/>
  		</material>
    </visual>
    <collision>
      <geometry>
        <mesh filename="package://meshes/collision/link0.obj"/>
      </geometry>
      <material name="panda_white"/>
    </collision>
  </link>
  <link name="panda_link1">
  	<inertial>
      <origin rpy="0 0 0" xyz="0 -0.04 -0.05"/>
       <mass value="2.7"/>
       <inertia ixx="0.1" ixy="0" ixz="0" iyy="0.1" iyz="0" izz="0.1"/>
    </inertial>
    <visual>
      <geometry>
        <mesh filename="package://meshes/visual/link1.obj"/>
      </geometry>
      <material name="panda_white"/>
    </visual>
    <collision>
      <geometry>
        <mesh filename="package://meshes/collision/link1.obj"/>
      </geometry>
      <material name="panda_white"/>
    </collision>
  </link>
  <joint name="panda_joint1" type="revolute">
    <safety_controller k_position="100.0" k_velocity="40.0" soft_lower_limit="-2.8973" soft_upper_limit="2.8973"/>
    <origin rpy="0 0 0" xyz="0 0 0.333"/>
    <parent link="panda_link0"/>
    <child link="panda_link1"/>
    <axis xyz="0 0 1"/>
    <limit effort="87" lower="-2.9671" upper="2.9671" velocity="2.1750"/>
  </joint>
  <link name="panda_link2">
  	<inertial>
      <origin rpy="0 0 0" xyz="0 -0.04 0.06"/>
       <mass value="2.73"/>
       <inertia ixx="0.1" ixy="0" ixz="0" iyy="0.1" iyz="0" izz="0.1"/>
    </inertial>
    <visual>
      <geometry>
        <mesh filename="package://meshes/visual/link2.obj"/>
      </geometry>
      <material name="panda_white"/>
    </visual>
    <collision>
      <geometry>
        <mesh filename="package://meshes/collision/link2.obj"/>
      </geometry>
      <material name="panda_white"/>
    </collision>
  </link>
  <joint name="panda_joint2" type="revolute">
    <safety_controller k_position="100.0" k_velocity="40.0" soft_lower_limit="-1.7628" soft_upper_limit="1.7628"/>
    <origin rpy="-1.57079632679 0 0" xyz="0 0 0"/>
    <parent link="panda_link1"/>
    <child link="panda_link2"/>
    <axis xyz="0 0 1"/>
    <limit effort="87" lower="-1.8326" upper="1.8326" velocity="2.1750"/>
  </joint>
  <link name="panda_link3">
	  <inertial>
      <origin rpy="0 0 0" xyz="0.01 0.01 -0.05"/>
       <mass value="2.04"/>
       <inertia ixx="0.1" ixy="0" ixz="0" iyy="0.1" iyz="0" izz="0.1"/>
    </inertial>
    <visual>
      <geometry>
        <mesh filename="package://meshes/visual/link3.obj"/>
      </geometry>
      <material name="panda_red">
    		<color rgba="1. 1. 1. 1."/>
  		</material>
    </visual>
    <collision>
      <geometry>
        <mesh filename="package://meshes/collision/link3.obj"/>
      </geometry>
    </collision>
  </link>
  <joint name="panda_joint3" type="revolute">
    <safety_controller k_position="100.0" k_velocity="40.0" soft_lower_limit="-2.8973" soft_upper_limit="2.8973"/>
    <origin rpy="1.57079632679 0 0" xyz="0 -0.316 0"/>
    <parent link="panda_link2"/>
    <child link="panda_link3"/>
    <axis xyz="0 0 1"/>
    <limit effort="87" lower="-2.9671" upper="2.9671" velocity="2.1750"/>
  </joint>
  <link name="panda_link4">
  	<inertial>
      <origin rpy="0 0 0" xyz="-0.03 0.03 0.02"/>
       <mass value="2.08"/>
       <inertia ixx="0.1" ixy="0" ixz="0" iyy="0.1" iyz="0" izz="0.1"/>
    </inertial>
    <visual>
      <geometry>
        <mesh filename="package://meshes/visual/link4.obj"/>
      </geometry>
      <material name="panda_white"/>
    </visual>
    <collision>
      <geometry>
        <mesh filename="package://meshes/collision/link4.obj"/>
      </geometry>
      <material name="panda_white"/>
    </collision>
  </link>
  <joint name="panda_joint4" type="revolute">
    <safety_controller k_position="100.0" k_velocity="40.0" soft_lower_limit="-3.0718" soft_upper_limit="-0.0698"/>
    <origin rpy="1.57079632679 0 0" xyz="0.0825 0 0"/>
    <parent link="panda_link3"/>
    <child link="panda_link4"/>
    <axis xyz="0 0 1"/>
    <limit effort="87" lower="-3.1416" upper="0.0" velocity="2.1750"/>
  </joint>
  <link name="panda_link5">
  	<inertial>
      <origin rpy="0 0 0" xyz="0 0.04 -0.12"/>
       <mass value="3"/>
       <inertia ixx="0.1" ixy="0" ixz="0" iyy="0.1" iyz="0" izz="0.1"/>
    </inertial>
    <visual>
      <geometry>
        <mesh filename="package://meshes/visual/link5.obj"/>
      </geometry>
      <material name="panda_white"/>
    </visual>
    <collision>
      <geometry>
        <mesh filename="package://meshes/collision/link5.obj"/>
      </geometry>
      <material name="panda_white"/>
    </collision>
  </link>
  <joint name="panda_joint5" type="revolute">
    <safety_controller k_position="100.0" k_velocity="40.0" soft_lower_limit="-2.8973" soft_upper_limit="2.8973"/>
    <origin rpy="-1.57079632679 0 0" xyz="-0.0825 0.384 0"/>
    <parent link="panda_link4"/>
    <child link="panda_link5"/>
    <axis xyz="0 0 1"/>
    <limit effort="12" lower="-2.9671" upper="2.9671" velocity="2.6100"/>
  </joint>
  <link name="panda_link6">
  	<inertial>
      <origin rpy="0 0 0" xyz="0.04 0 0"/>
       <mass value="1.3"/>
       <inertia ixx="0.1" ixy="0" ixz="0" iyy="0.1" iyz="0" izz="0.1"/>
    </inertial>
    <visual>
      <geometry>
        <mesh filename="package://meshes/visual/link6.obj"/>
      </geometry>
      <material name="panda_white"/>
    </visual>
    <collision>
      <geometry>
        <mesh filename="package://meshes/collision/link6.obj"/>
      </geometry>
      <material name="panda_white"/>
    </collision>
  </link>
  <joint name="panda_joint6" type="revolute">
    <safety_controller k_position="100.0" k_velocity="40.0" soft_lower_limit="-0.0175" soft_upper_limit="3.7525"/>
    <origin rpy="1.57079632679 0 0" xyz="0 0 0"/>
    <parent link="panda_link5"/>
    <child link="panda_link6"/>
    <axis xyz="0 0 1"/>
    <limit effort="12" lower="-0.0873" upper="3.8223" velocity="2.6100"/>
  </joint>
  <link name="panda_link7">
  	<inertial>
      <origin rpy="0 0 0" xyz="0 0 0.08"/>
       <mass value=".2"/>
       <inertia ixx="0.1" ixy="0" ixz="0" iyy="0.1" iyz="0" izz="0.1"/>
    </inertial>
    <visual>
      <geometry>
        <mesh filename="package://meshes/collision/link7.obj"/>
      </geometry>
      <material name="panda_white"/>
    </visual>
    <collision>
      <geometry>
        <mesh filename="package://meshes/collision/link7.obj"/>
      </geometry>
      <material name="panda_white"/>
    </collision>
  </link>
  <joint name="panda_joint7" type="revolute">
    <safety_controller k_position="100.0" k_velocity="40.0" soft_lower_limit="-2.8973" soft_upper_limit="2.8973"/>
    <origin rpy="1.57079632679 0 0" xyz="0.088 0 0"/>
    <parent link="panda_link6"/>
    <child link="panda_link7"/>
    <axis xyz="0 0 1"/>
    <limit effort="12" lower="-2.9671" upper="2.9671" velocity="2.6100"/>
  </joint>


  <!--################################################
  ########               camera                  #####
  ####################################################-->

  <joint name="bracket_joint" type="fixed">
    <parent link="panda_link7"/>
    <child link="bracket"/>
    <origin rpy="0.0 0.0 0.7744200424" xyz="0.0 0.0 0.098"/>
  </joint>

  <link name="bracket">
    <inertial>
      <origin rpy="0 0 0" xyz="0 0 0.0"/>
       <mass value=".2"/>
       <inertia ixx="0.1" ixy="0" ixz="0" iyy="0.1" iyz="0" izz="0.1"/>
    </inertial>
    <visual>
      <geometry>
        <mesh filename="meshes2/visual/panda_bracket.stl"/>
      </geometry>
      <material name="qq">
        <color rgba="0.8 0.8 0.8 1.0"/>
      </material>
    </visual>
    <collision>
      <geometry>
         <mesh filename="meshes2/visual/panda_bracket.stl"/>
      </geometry>
    </collision>
  </link>
  
  <joint name="camera_joint" type="fixed">
    <parent link="bracket"/>
    <child link="camera"/>
    <origin rpy="0.0 0.0 -1.57079632679" xyz="0.0 -0.082 0.0762"/>
  </joint>

  <link name="camera">
    <inertial>
      <origin rpy="0 0 0" xyz="0 0 0.0"/>
       <mass value=".5"/>
       <inertia ixx="0.1" ixy="0" ixz="0" iyy="0.1" iyz="0" izz="0.1"/>
    </inertial>
    <visual>
      <geometry>
        <mesh filename="meshes2/visual/Azure_Kinect_DK.stl"/>
      </geometry>
      <material name="aa">
        <color rgba="0.7 0.7 0.7 1.0"/>
      </material>
    </visual>
    <collision>
      <geometry>
         <mesh filename="meshes2/visual/Azure_Kinect_DK.stl"/>
      </geometry>
    </collision>
  </link>

  <!--################################################
  ########              gripper                  #####
  ####################################################-->

  <joint name="robotiq_85_coupling_joint" type="fixed">
    <parent link="bracket"/>
    <child link="robotiq_85_coupling_link"/>
    <origin rpy="0.0 0.0 0.0" xyz="0.0 0.0 0.07"/>
  </joint>

  <link name="end_effector_indicator_link">
    <visual>
      <geometry>
        <box size="0.023 0.014 0.036"/>
      </geometry>
      <material name="RED">
        <color rgba="1.0 0.1 0.1 1.0"/>
      </material>
    </visual>
  </link>

  <joint name="end_effector_fixed_joint" type="fixed">
    <parent link="robotiq_85_base_link"/>
    <child link="end_effector_indicator_link"/>
    <origin rpy="0.0 1.57079632679 0.0" xyz="0.146 0 0" />
  </joint>

  <link name="robotiq_85_coupling_link">
    <visual>
      <geometry>
        <mesh filename="meshes2/visual/robotiq_gripper_coupling.stl"/>
      </geometry>
      <material name="Silver">
        <color rgba="0.2 0.2 0.25 1.0"/>
      </material>
    </visual>
    <collision>
      <geometry>
        <mesh filename="meshes2/visual/robotiq_gripper_coupling.stl"/>
      </geometry>
    </collision>
    <inertial>
      <mass value="0.336951" />
      <origin xyz="0.0 0.0 0.0" />
      <inertia ixx = "0.000380" ixy = "0.000000" ixz = "0.000000"
           iyx = "0.000000" iyy = "0.001110" iyz = "0.000000"
           izx = "0.000000" izy = "0.000000" izz = "0.001171" />
    </inertial>
  </link>
  <joint name="robotiq_85_base_joint" type="fixed">
    <parent link="robotiq_85_coupling_link"/>
    <child link="robotiq_85_base_link"/>
    <origin rpy="0.0 -1.57079632679 1.57079632679" xyz="0.0 0.0 0.004"/>
  </joint>

  <link name="robotiq_85_base_link">
    <visual>
      <geometry>
        <mesh filename="meshes2/visual/robotiq_85_base_link.dae"/>
      </geometry>
      <material name="Silver">
        <color rgba="0.2 0.2 0.25 1.0"/>
      </material>
    </visual>
    <collision>
      <geometry>
        <mesh filename="meshes2/collision/robotiq_85_base_link.stl"/>
      </geometry>
    </collision>
    <inertial>
      <mass value="0.636951" />
      <origin xyz="0.0 0.0 0.0" />
      <inertia ixx = "0.000380" ixy = "0.000000" ixz = "0.000000"
           iyx = "0.000000" iyy = "0.001110" iyz = "0.000000"
           izx = "0.000000" izy = "0.000000" izz = "0.001171" />
    </inertial>
  </link>

  <joint name="robotiq_85_left_knuckle_joint" type="fixed">
    <parent link="robotiq_85_base_link"/>
    <child link="robotiq_85_left_knuckle_link"/>
    <axis xyz="0 0 1"/>
    <origin rpy="3.14 0.0 -0.80285" xyz="0.05490451627 0.03060114443 0.0"/>
    <limit lower="0.0" upper="0.80285" velocity="3.14" effort="1000"/>
  </joint>

  <joint name="robotiq_85_right_knuckle_joint" type="fixed">
    <parent link="robotiq_85_base_link"/>
    <child link="robotiq_85_right_knuckle_link"/>
    <axis xyz="0 0 1"/>
    <origin rpy="0.0 0.0 0.80285" xyz="0.05490451627 -0.03060114443 0.0"/>
    <limit lower="-3.14" upper="3.14" velocity="3.14" effort="1000"/>
    <mimic joint="robotiq_85_left_knuckle_joint"/>
  </joint>

  <link name="robotiq_85_left_knuckle_link">
    <visual>
      <geometry>
        <mesh filename="meshes2/visual/robotiq_85_knuckle_link.dae"/>
      </geometry>
      <material name="Sil">
        <color rgba="0.7 0.7 0.7 1.0"/>
      </material>
    </visual>
    <collision>
      <geometry>
        <mesh filename="meshes2/collision/robotiq_85_knuckle_link.stl"/>
      </geometry>
    </collision>
    <inertial>
      <mass value="0.018491" />
      <origin xyz="0.0 0.0 0.0" />
      <inertia ixx = "0.000009" ixy = "-0.000001" ixz = "0.000000"
           iyx = "-0.000001" iyy = "0.000001" iyz = "0.000000"
           izx = "0.000000" izy = "0.000000" izz = "0.000010" />
    </inertial>
  </link>

  <link name="robotiq_85_right_knuckle_link">
    <visual>
      <geometry>
        <mesh filename="meshes2/visual/robotiq_85_knuckle_link.dae"/>
      </geometry>
      <material name="Sil">
        <color rgba="0.7 0.7 0.7 1.0"/>
      </material>
    </visual>
    <collision>
      <geometry>
        <mesh filename="meshes2/collision/robotiq_85_knuckle_link.stl"/>
      </geometry>
    </collision>
    <inertial>
      <mass value="0.018491" />
      <origin xyz="0.0 0.0 0.0" />
      <inertia ixx = "0.000009" ixy = "-0.000001" ixz = "0.000000"
           iyx = "-0.000001" iyy = "0.000001" iyz = "0.000000"
           izx = "0.000000" izy = "0.000000" izz = "0.000010" />
    </inertial>
  </link>

  <joint name="robotiq_85_left_finger_joint" type="fixed">
    <parent link="robotiq_85_left_knuckle_link"/>
    <child link="robotiq_85_left_finger_link"/>
    <origin xyz="-0.00408552455 -0.03148604435 0.0" rpy="0 0 0" />
  </joint>

  <joint name="robotiq_85_right_finger_joint" type="fixed">
    <parent link="robotiq_85_right_knuckle_link"/>
    <child link="robotiq_85_right_finger_link"/>
    <origin xyz="-0.00408552455 -0.03148604435 0.0" rpy="0 0 0" />
  </joint>

  <link name="robotiq_85_left_finger_link">
    <visual>
      <geometry>
        <mesh filename="meshes2/visual/robotiq_85_finger_link.dae"/>
      </geometry>
      <material name="Silver">
        <color rgba="0.2 0.2 0.25 1.0"/>
      </material>
    </visual>
    <collision>
      <geometry>
        <mesh filename="meshes2/collision/robotiq_85_finger_link.stl"/>
      </geometry>
    </collision>
    <inertial>
      <mass value="0.027309" />
      <origin xyz="0.0 0.0 0.0" />
      <inertia ixx = "0.000003" ixy = "-0.000002" ixz = "0.000000"
           iyx = "-0.000002" iyy = "0.000021" iyz = "0.000000"
           izx = "0.000000" izy = "0.000000" izz = "0.000020" />
    </inertial>
  </link>

  <link name="robotiq_85_right_finger_link">
    <visual>
      <geometry>
        <mesh filename="meshes2/visual/robotiq_85_finger_link.dae"/>
      </geometry>
      <material name="Silver">
        <color rgba="0.2 0.2 0.25 1.0"/>
      </material>
    </visual>
    <collision>
      <geometry>
        <mesh filename="meshes2/collision/robotiq_85_finger_link.stl"/>
      </geometry>
    </collision>
    <inertial>
      <mass value="0.027309" />
      <origin xyz="0.0 0.0 0.0" />
      <inertia ixx = "0.000003" ixy = "-0.000002" ixz = "0.000000"
           iyx = "-0.000002" iyy = "0.000021" iyz = "0.000000"
           izx = "0.000000" izy = "0.000000" izz = "0.000020" />
    </inertial>
  </link>

  <joint name="robotiq_85_left_inner_knuckle_joint" type="fixed">
    <parent link="robotiq_85_base_link"/>
    <child link="robotiq_85_left_inner_knuckle_link"/>
    <axis xyz="0 0 1"/>
    <origin xyz="0.06142 0.0127 0" rpy="3.14 0.0 -0.80285" />
    <limit lower="-3.14" upper="3.14" velocity="3.14" effort="0.1"/>
    <mimic joint="robotiq_85_left_knuckle_joint" offset="0"/>
  </joint>

  <joint name="robotiq_85_right_inner_knuckle_joint" type="fixed">
    <parent link="robotiq_85_base_link"/>
    <child link="robotiq_85_right_inner_knuckle_link"/>
    <axis xyz="0 0 1"/>
    <origin xyz="0.06142 -0.0127 0" rpy="0 0 0.80285"/>
    <limit lower="-3.14" upper="3.14" velocity="3.14" effort="0.1"/>
    <mimic joint="robotiq_85_left_knuckle_joint" offset="0"/>
  </joint>

  <link name="robotiq_85_left_inner_knuckle_link">
    <visual>
      <geometry>
        <mesh filename="meshes2/visual/robotiq_85_inner_knuckle_link.dae"/>
      </geometry>
      <material name="Silver">
        <color rgba="0.2 0.2 0.25 1.0"/>
      </material>
    </visual>
    <collision>
      <geometry>
        <mesh filename="meshes2/collision/robotiq_85_inner_knuckle_link.stl"/>
      </geometry>
    </collision>
    <inertial>
      <mass value="0.029951" />
      <origin xyz="0.0 0.0 0.0" />
      <inertia ixx = "0.000039" ixy = "0.000000" ixz = "0.000000"
           iyx = "0.000000" iyy = "0.000005" iyz = "0.000000"
           izx = "0.000000" izy = "0.000000" izz = "0.000035" />
    </inertial>
  </link>
  <link name="robotiq_85_right_inner_knuckle_link">
    <visual>
      <geometry>
        <mesh filename="meshes2/visual/robotiq_85_inner_knuckle_link.dae"/>
      </geometry>
      <material name="Silver">
        <color rgba="0.2 0.2 0.25 1.0"/>
      </material>
    </visual>
    <collision>
      <geometry>
        <mesh filename="meshes2/collision/robotiq_85_inner_knuckle_link.stl"/>
      </geometry>
    </collision>
    <inertial>
      <mass value="0.029951" />
      <origin xyz="0.0 0.0 0.0" />
      <inertia ixx = "0.000039" ixy = "0.000000" ixz = "0.000000"
           iyx = "0.000000" iyy = "0.000005" iyz = "0.000000"
           izx = "0.000000" izy = "0.000000" izz = "0.000035" />
    </inertial>
  </link>

  <joint name="robotiq_85_left_finger_tip_joint" type="fixed">
    <parent link="robotiq_85_left_inner_knuckle_link"/>
    <child link="robotiq_85_left_finger_tip_link"/>
    <axis xyz="0 0 1"/>
    <origin xyz="0.04303959807 -0.03759940821 0.0" rpy="0.0 0.0 -0.80285"/>
    <limit lower="-3.14" upper="3.14" velocity="3.14" effort="0.1"/>
    <mimic joint="robotiq_85_left_knuckle_joint" multiplier="-1"/>
  </joint>

  <joint name="robotiq_85_right_finger_tip_joint" type="fixed">
    <parent link="robotiq_85_right_inner_knuckle_link"/>
    <child link="robotiq_85_right_finger_tip_link"/>
    <axis xyz="0 0 1"/>
    <origin rpy="0.0 0.0 -0.80285" xyz="0.04303959807 -0.03759940821  0.0"/>
    <limit lower="-3.14" upper="3.14" velocity="3.14" effort="0.1"/>
    <mimic joint="robotiq_85_left_knuckle_joint" multiplier="-1"/>
  </joint>


  <link name="robotiq_85_left_finger_tip_link">
    <visual>
      <geometry>
        <mesh filename="meshes2/visual/robotiq_85_finger_tip_link.dae"/>
      </geometry>
      <material name="Silver">
        <color rgba="0.2 0.2 0.25 1.0"/>
      </material>
    </visual>
    <collision>
      <geometry>
        <mesh filename="meshes2/collision/robotiq_85_finger_tip_link.stl"/>
      </geometry>
    </collision>
    <inertial>
      <mass value="0.019555" />
      <origin xyz="0.0 0.0 0.0" />
      <inertia ixx = "0.000002" ixy = "0.000000" ixz = "0.000000"
           iyx = "0.000000" iyy = "0.000005" iyz = "0.000000"
           izx = "0.000000" izy = "0.000000" izz = "0.000006" />
    </inertial>
  </link>

  <link name="robotiq_85_right_finger_tip_link">
    <visual>
      <geometry>
        <mesh filename="meshes2/visual/robotiq_85_finger_tip_link.dae"/>
      </geometry>
      <material name="Silver">
        <color rgba="0.2 0.2 0.25 1.0"/>
      </material>
    </visual>
    <collision>
      <geometry>
        <mesh filename="meshes2/collision/robotiq_85_finger_tip_link.stl"/>
      </geometry>
    </collision>
    <inertial>
      <mass value="0.019555" />
      <origin xyz="0.0 0.0 0.0" />
      <inertia ixx = "0.000002" ixy = "0.000000" ixz = "0.000000"
           iyx = "0.000000" iyy = "0.000005" iyz = "0.000000"
           izx = "0.000000" izy = "0.000000" izz = "0.000006" />
    </inertial>
  </link>
  
  
</robot>
